Traceback (most recent call last):
  File "c:\Users\user\Documents\GitHub\study-app-project\services\enhanced_openai_service.py", line 284, in call_openai_api
    print("\U0001f512 プライバシー保護: OpenAI学習無効化ヘッダー送信完了 (汎用API)")
UnicodeEncodeError: 'cp932' codec can't encode character '\U0001f512' in position 0: illegal multibyte sequence

During handling of the above exception, another exception occurred:

Traceback (most recent call last):
  File "c:\Users\user\Documents\GitHub\study-app-project\debug_simple_extraction.py", line 86, in test_openai_connection
    response = service.call_openai_api(
               ^^^^^^^^^^^^^^^^^^^^^^^^
  File "c:\Users\user\Documents\GitHub\study-app-project\services\enhanced_openai_service.py", line 319, in call_openai_api
    print(f"\u274c Unexpected error on attempt {attempt + 1}: {e}")
UnicodeEncodeError: 'cp932' codec can't encode character '\u274c' in position 0: illegal multibyte sequence
==================================================
過去問抽出デバッグテスト
==================================================
OpenAI接続テスト...
OK: API Key確認済み: sk-proj-no...
ERROR: OpenAI接続テストエラー: 'cp932' codec can't encode character '\u274c' in position 0: illegal multibyte sequence

ERROR: OpenAI接続テストが失敗しました
