==================================================
過去問抽出デバッグテスト
==================================================
Traceback (most recent call last):
  File "c:\Users\user\Documents\GitHub\study-app-project\debug_simple_extraction.py", line 71, in test_openai_connection
    print("\U0001f511 OpenAI接続テスト...")
UnicodeEncodeError: 'cp932' codec can't encode character '\U0001f511' in position 0: illegal multibyte sequence

During handling of the above exception, another exception occurred:

Traceback (most recent call last):
  File "c:\Users\user\Documents\GitHub\study-app-project\debug_simple_extraction.py", line 113, in <module>
    if test_openai_connection():
       ^^^^^^^^^^^^^^^^^^^^^^^^
  File "c:\Users\user\Documents\GitHub\study-app-project\debug_simple_extraction.py", line 102, in test_openai_connection
    print(f"\u274c OpenAI接続テストエラー: {e}")
UnicodeEncodeError: 'cp932' codec can't encode character '\u274c' in position 0: illegal multibyte sequence
